i-0f425bb12c09f2af3.ec2.internal
*** Found local files:
***   * /home/ubuntu/airflow/logs/dag_id=data_engineering_job/run_id=manual__2024-09-10T09:20:24.611024+00:00/task_id=pull_latest_code/attempt=2.log
[2024-09-10, 09:25:34 UTC] {taskinstance.py:1103} INFO - Dependencies all met for dep_context=non-requeueable deps ti=<TaskInstance: data_engineering_job.pull_latest_code manual__2024-09-10T09:20:24.611024+00:00 [queued]>
[2024-09-10, 09:25:34 UTC] {taskinstance.py:1103} INFO - Dependencies all met for dep_context=requeueable deps ti=<TaskInstance: data_engineering_job.pull_latest_code manual__2024-09-10T09:20:24.611024+00:00 [queued]>
[2024-09-10, 09:25:34 UTC] {taskinstance.py:1308} INFO - Starting attempt 2 of 2
[2024-09-10, 09:25:34 UTC] {taskinstance.py:1327} INFO - Executing <Task(BashOperator): pull_latest_code> on 2024-09-10 09:20:24.611024+00:00
[2024-09-10, 09:25:34 UTC] {standard_task_runner.py:57} INFO - Started process 77974 to run task
[2024-09-10, 09:25:34 UTC] {standard_task_runner.py:84} INFO - Running: ['airflow', 'tasks', 'run', 'data_engineering_job', 'pull_latest_code', 'manual__2024-09-10T09:20:24.611024+00:00', '--job-id', '453', '--raw', '--subdir', 'DAGS_FOLDER/l2Job.py', '--cfg-path', '/tmp/tmp6ypvh42w']
[2024-09-10, 09:25:34 UTC] {standard_task_runner.py:85} INFO - Job 453: Subtask pull_latest_code
[2024-09-10, 09:25:34 UTC] {task_command.py:410} INFO - Running <TaskInstance: data_engineering_job.pull_latest_code manual__2024-09-10T09:20:24.611024+00:00 [running]> on host i-0f425bb12c09f2af3.ec2.internal
[2024-09-10, 09:25:34 UTC] {taskinstance.py:1545} INFO - Exporting env vars: AIRFLOW_CTX_DAG_OWNER='airflow' AIRFLOW_CTX_DAG_ID='data_engineering_job' AIRFLOW_CTX_TASK_ID='pull_latest_code' AIRFLOW_CTX_EXECUTION_DATE='2024-09-10T09:20:24.611024+00:00' AIRFLOW_CTX_TRY_NUMBER='2' AIRFLOW_CTX_DAG_RUN_ID='manual__2024-09-10T09:20:24.611024+00:00'
[2024-09-10, 09:25:34 UTC] {subprocess.py:63} INFO - Tmp dir root location: /tmp
[2024-09-10, 09:25:34 UTC] {subprocess.py:75} INFO - Running command: ['/usr/bin/bash', '-c', 'cd /home/ubuntu && git pull']
[2024-09-10, 09:25:34 UTC] {subprocess.py:86} INFO - Output:
[2024-09-10, 09:25:34 UTC] {subprocess.py:93} INFO - fatal: not a git repository (or any of the parent directories): .git
[2024-09-10, 09:25:34 UTC] {subprocess.py:97} INFO - Command exited with return code 128
[2024-09-10, 09:25:34 UTC] {taskinstance.py:1824} ERROR - Task failed with exception
Traceback (most recent call last):
  File "/home/ubuntu/airflow_venv/lib/python3.10/site-packages/airflow/operators/bash.py", line 210, in execute
    raise AirflowException(
airflow.exceptions.AirflowException: Bash command failed. The command returned a non-zero exit code 128.
[2024-09-10, 09:25:34 UTC] {taskinstance.py:1345} INFO - Marking task as FAILED. dag_id=data_engineering_job, task_id=pull_latest_code, execution_date=20240910T092024, start_date=20240910T092534, end_date=20240910T092534
[2024-09-10, 09:25:34 UTC] {standard_task_runner.py:104} ERROR - Failed to execute job 453 for task pull_latest_code (Bash command failed. The command returned a non-zero exit code 128.; 77974)
[2024-09-10, 09:25:34 UTC] {local_task_job_runner.py:225} INFO - Task exited with return code 1
[2024-09-10, 09:25:34 UTC] {taskinstance.py:2653} INFO - 0 downstream tasks scheduled from follow-on schedule check
